Workbook

Sheet Old - Do Not Use
B1: Inception to FY25 | C1: FY26 | D1: FY27 | E1: FY28 | F1: FY29 | G1: FY30
A2: User & Subscription Growth
A3: Total FIT Volume | C3: 240000 | D3: 350000 | E3: 500000 | F3: 600000 | G3: 700000
A4: RA Volume
A5: Altherma Volume
A6: FY Thermostats (all brands) | B6: 610064 | C6: 240000 | D6: 350000 | E6: 500000 | F6: 600000 | G6: 700000
A7: Total Thermostats (all brands) | B7: 610064 | C7: =B7+C6 -> 850064 | D7: =C7+D6 -> 1200064 | E7: =D7+E6 -> 1700064 | F7: =E7+F6 -> 2300064 | G7: =F7+G6 -> 3000064
A8: FY Connected Thermostats | B8: 341000 | C8: =C9*C6 -> 144000 | D8: =D9*D6 -> 227500 | E8: =E9*E6 -> 350000 | F8: =F9*F6 -> 450000 | G8: =G9*G6 -> 560000
A9: % of FY Connected Thermostats | B9: =B10/B7 -> 0.55895775 | C9: 0.6 | D9: 0.65 | E9: 0.7 | F9: 0.75 | G9: 0.8
A10: Total Connected Thermostats | B10: =B8 -> 341000 | C10: =B10+C8 -> 485000 | D10: =C10+D8 -> 712500 | E10: =D10+E8 -> 1062500 | F10: =E10+F8 -> 1512500 | G10: =F10+G8 -> 2072500
A11: SkyportHome
A12: Users (%)
A13: FIT | B13: =B17/B6 -> 0.49175169 | C13: 0.6 | D13: 0.65 | E13: 0.7 | F13: 0.75 | G13: 0.8
A14: RA | C14: 0.05 | D14: 0.1 | E14: 0.2 | F14: 0.3 | G14: 0.4
A15: Altherma | B15: 0% | C15: 0.05 | D15: 0.1 | E15: 0.2 | F15: 0.3 | G15: 0.4
A16: Users only for the FY | C16: =C13*C3+C14*C4+C15*C5 -> 144000 | D16: =D13*D3+D14*D4+D15*D5 -> 227500 | E16: =E13*E3+E14*E4+E15*E5 -> 350000 | F16: =F13*F3+F14*F4+F15*F5 -> 450000 | G16: =G13*G3+G14*G4+G15*G5 -> 560000
A17: Total Users | B17: 300000 | C17: =B17+C16 -> 444000 | D17: =C17+D16 -> 671500 | E17: =D17+E16 -> 1021500 | F17: =E17+F16 -> 1471500 | G17: =F17+G16 -> 2031500
A18: SkyportCare
A19: Subscribers (%)
A20: Annual Included (attachment) | C20: 1 | D20: 1 | E20: 1 | F20: 1 | G20: 1
A21: Annual | B21: =B25/B17 -> 0.00097666667 | C21: 0.03 | D21: 0.04 | E21: 0.06 | F21: 0.08 | G21: 0.12
A22: Lifetime | B22: =B26/B17 -> 0.0061133333 | C22: 0.03 | D22: 0.08 | E22: 0.1 | F22: 0.12 | G22: 0.16
A23: Subscribers | D23: =D24-C24 -> 110000 | E23: =E24-D24 -> 150000 | F23: =F24-E24 -> 100000 | G23: =G24-F24 -> 100000
A24: Bundled Active Licenses | B24: 9545 | C24: =C20*C6 -> 240000 | D24: =D20*D6 -> 350000 | E24: =E20*E6 -> 500000 | F24: =F20*F6 -> 600000 | G24: =G20*G6 -> 700000
A25: Annual Active Licenses | B25: 293 | C25: =C21*(C17-C16) -> 9000 | D25: =D21*(D17-D16) -> 17760 | E25: =E21*(E17-E16) -> 40290 | F25: =F21*(F17-F16) -> 81720 | G25: =G21*(G17-G16) -> 176580
A26: Lifetime Active Licenses | B26: 1834 | C26: =C22*(C17-C16) -> 9000 | D26: =D22*(D17-D16) -> 35520 | E26: =E22*(E17-E16) -> 67150 | F26: =F22*(F17-F16) -> 122580 | G26: =G22*(G17-G16) -> 235440
A27: Active License Penetration | B27: =(B25+B26)/B17 -> 0.00709 | C27: =(C25+C26)/C16 -> 0.125 | D27: =(D25+D26)/D16 -> 0.2341978 | E27: =(E25+E26)/E16 -> 0.30697143 | F27: =(F25+F26)/F16 -> 0.454 | G27: =(G25+G26)/G16 -> 0.73575
A28: Revenue
A29: #1 SkyportCare License Revenue
A30: Annual License Fee | C30: 60 | D30: 60 | E30: 60 | F30: 60 | G30: 60
A31: Lifetime License Fee | C31: 400 | D31: 400 | E31: 400 | F31: 400 | G31: 400
A32: Annual Included (attachment) ($) | C32: =C20*C30*C6 -> 14400000 | D32: =D20*D30*D6 -> 21000000 | E32: =E20*E30*E6 -> 30000000 | F32: =F20*F30*F6 -> 36000000 | G32: =G20*G30*G6 -> 42000000
A33: Annual ($) | C33: =C30*C25 -> 540000 | D33: =D30*D25 -> 1065600 | E33: =E30*E25 -> 2417400 | F33: =F30*F25 -> 4903200 | G33: =G30*G25 -> 10594800
A34: Lifetime ($) | C34: =C31*C26 -> 3600000 | D34: =D31*D26 -> 14208000 | E34: =E31*E26 -> 26860000 | F34: =F31*F26 -> 49032000 | G34: =G31*G26 -> 94176000
A35: Total ($) | C35: =SUM(C32:C34) -> 18540000 | D35: =SUM(D32:D34) -> 36273600 | E35: =SUM(E32:E34) -> 59277400 | F35: =SUM(F32:F34) -> 89935200 | G35: =SUM(G32:G34) -> 146770800
A36: #2 SkyportCare Enterprise License Revenue
A37: Per unit annual License Fee | C37: 30 | D37: 30 | E37: 30 | F37: 30 | G37: 30
A38: No. of Units per Enterprise Customer | C38: 50 | D38: 50 | E38: 50 | F38: 50 | G38: 50
A39: No. of Enterprise Customers | C39: 20 | D39: =C39*4 -> 80 | E39: =D39*4 -> 320 | F39: =E39*4 -> 1280 | G39: =F39*4 -> 5120
A40: Total ($) | C40: =C39*C38*C37 -> 30000 | D40: =D39*D38*D37 -> 120000 | E40: =E39*E38*E37 -> 480000 | F40: =F39*F38*F37 -> 1920000 | G40: =G39*G38*G37 -> 7680000
...

Sheet Definitions
A1: Phase | B1: HEMS | C1: Package | D1: Technology | E1: Definition
A2: 1 | B2: TOU | C2: Conserve | D2: HVAC | E2: Minimize energy load during peak ToU periods, pre-cool and Pre‑heat home & participation in setpoint nudges, etc.
A3: 2 | B3: VPP | C3: Offset | D3: HVAC | E3: HVAC used as a grid asset and utilities pay for capacity, performance, etc.
A4: 3 | B4: Complete | C4: Smart | D4: HVAC, Solar, Storage, MSP, Appliances, EV charger & more | E4: Whole-home DR and VPP

Sheet Assumptions
A1: Assumptions | B1: Avg. electricity bill (monthly) | C1: 150
B2: Avg. electricity bill (yearly) | C2: =12*C1 -> 1800
B3: HVAC share of electricity (40% - 60%) | C3: 0.5 | G3: Enterprise Segment
B4: Annual electricity cost from HVAC | C4: =C3*C2 -> 900 | G4: User Type | H4: Target Application | I4: # of relationships | J4: Avg. no. of units/site
G5: Building Owner | H5: Office | I5: 5 | J5: 10
A6: Phase | B6: Homeowner Savings Components | D6: Year | G6: Facilities Manager | H6: School | I6: 20 | J6: 10
A7: 1 | B7: HO: TOU % energy savings (15% - 25%) | C7: 0.2 | D7: 2028 | G7: Property Management | H7: Builder | I7: 10 | J7: 5
B8: HO: TOU $ energy savings | C8: =C7*C4 -> 180 | G8: Rep/Contractor | H8: C&I | I8: 5 | J8: 5
B9: HO: Utility DR Incentives ($10/month average) | C9: 120 | G9: Multi-fly/multi-tenant | H9: Apt/Condo | I9: 50 | J9: 150
B10: HO: Annual savings | C10: =C8+C9 -> 300 | I10: =AVERAGE(I5:I9) -> 18 | J10: =AVERAGE(J5:J9) -> 36
B11: TOU Fee % for guarenteed savings: 20% - 40% | C11: 0.25
B12: TOU Fee $ for guarenteed savings | C12: =C11*C10 -> 75
B13: HO: Net Annual Savings | C13: =C10-C12 -> 225
B14: TOU Aggregator fee % (like Leap) | C14: 0.1
B15: TOU Aggregator fee $ (like Leap) | C15: =C14*C12 -> 7.5
B16: TOU Daikin Revenue | C16: =C12-C15 -> 67.5
A17: 2 | B17: HO: Annual savings (Phase 1) | C17: =C10 -> 300 | D17: 2029
B18: VPP Payment | C18: 150
B19: HO: VPP participation payment % | C19: 0.5
B20: HO: VPP participation payment $ | C20: =C19*C18 -> 75
B21: HO: Total Annual Savings (Phase 1 & 2) | C21: =C17+C20 -> 375
B22: Fees for Aggregator and Daikin | C22: =C18-C20 -> 75
B23: VPP Aggregator fee % (like Leap) | C23: 0.2
B24: VPP Aggregator fee $ (like Leap) | C24: =C22*C23 -> 15
B25: TOU Daikin Revenue | C25: =C16 -> 67.5
B26: VPP Daikin Revenue | C26: =C22-C24 -> 60
B27: Daikin Revenue (TOU + VPP) | C27: =C25+C26 -> 127.5
A28: 3 | B28: HVAC: TOU Savings | C28: =C10 -> 300 | D28: 2030
B29: HVAC: VPP Payment | C29: =C18 -> 150
B30: Solar + Battery TOU Savings | C30: 600
B31: Solar + Battery: VPP Payment | C31: 350
B32: EV Charging: TOU Savings | C32: 400
B33: EV Charging: VPP Payment | C33: 100
B34: HP Water Heater: TOU Savings | C34: 120
B35: HP Water Heater: VPP Payment | C35: 80
B36: Total HO TOU Savings | C36: =C28+C32+C34+C30 -> 1420
B37: Total HO VPP Payment | C37: =C29+C31+C33+C35 -> 680
B38: Total HO TOU Savings except HVAC | C38: =C30+C32+C34 -> 1120
B39: TOU Fee $ for guarenteed savings | C39: =C11*C38 -> 280
B40: TOU Aggregator fee $ (like Leap) | C40: =C14*C39 -> 28
...

Sheet Future Model Growth
B1: Till Date | C1: FY26 | D1: FY27 | E1: FY28 | F1: FY29 | G1: FY30
A2: User & Subscription Growth
A3: Total FIT Volume | C3: 240000 | D3: 350000 | E3: 500000 | F3: 600000 | G3: 700000
A4: RA Volume
A5: Altherma Volume
A6: Thermostats (all brands) | B6: 500000 | C6: 240000 | D6: 350000 | E6: 500000 | F6: 600000 | G6: 700000
A7: SkyportHome
A8: Users (%)
A9: FIT | B9: =B13/B6 -> 0.56 | C9: 0.6 | D9: 0.65 | E9: 0.7 | F9: 0.75 | G9: 0.8
A10: RA | C10: 0.05 | D10: 0.1 | E10: 0.2 | F10: 0.3 | G10: 0.4
A11: Altherma | C11: 0.05 | D11: 0.1 | E11: 0.2 | F11: 0.3 | G11: 0.4
A12: Users only for the FY | C12: =C9*C3+C10*C4+C11*C5 -> 144000 | D12: =D9*D3+D10*D4+D11*D5 -> 227500 | E12: =E9*E3+E10*E4+E11*E5 -> 350000 | F12: =F9*F3+F10*F4+F11*F5 -> 450000 | G12: =G9*G3+G10*G4+G11*G5 -> 560000
A13: Total Users | B13: 280000 | C13: =B13+C12 -> 424000 | D13: =C13+D12 -> 651500 | E13: =D13+E12 -> 1001500 | F13: =E13+F12 -> 1451500 | G13: =F13+G12 -> 2011500
A14: SkyportCare
A15: Subscribers (%)
A16: Annual Included (attachment) | C16: 1 | D16: 1 | E16: 1 | F16: 1 | G16: 1
A17: Monthly | C17: 0.05 | D17: 0.1 | E17: 0.14 | F17: 0.18 | G17: 0.22
A18: Annual | B18: =B23/B13 -> 0.0010464286 | C18: 0.03 | D18: 0.04 | E18: 0.06 | F18: 0.08 | G18: 0.12
A19: Lifetime | B19: =B24/B13 -> 0.00655 | C19: 0.03 | D19: 0.08 | E19: 0.1 | F19: 0.12 | G19: 0.16
A20: Subscribers
A21: Annual Included (attachment) | B21: 8174 | C21: =C16*C6 -> 240000 | D21: =D16*D6 -> 350000 | E21: =E16*E6 -> 500000 | F21: =F16*F6 -> 600000 | G21: =G16*G6 -> 700000
A22: Monthly | C22: =(C13-C12)*C17 -> 14000 | D22: =(D13-D12)*D17 -> 42400 | E22: =(E13-E12)*E17 -> 91210 | F22: =(F13-F12)*F17 -> 180270 | G22: =(G13-G12)*G17 -> 319330
A23: Annual | B23: 293 | C23: =C18*(C13-C12) -> 8400 | D23: =D18*(D13-D12) -> 16960 | E23: =E18*(E13-E12) -> 39090 | F23: =F18*(F13-F12) -> 80120 | G23: =G18*(G13-G12) -> 174180
A24: Lifetime | B24: 1834 | C24: =C19*(C13-C12) -> 8400 | D24: =D19*(D13-D12) -> 33920 | E24: =E19*(E13-E12) -> 65150 | F24: =F19*(F13-F12) -> 120180 | G24: =G19*(G13-G12) -> 232240
A26: Revenue
A27: #1 SkyportCare License Revenue
A28: Monthly License Fee ($8/month) | C28: 96 | D28: 96 | E28: 96 | F28: 96 | G28: 96
A29: Annual License Fee | C29: 60 | D29: 60 | E29: 60 | F29: 60 | G29: 60
A30: Lifetime License Fee | C30: 400 | D30: 400 | E30: 400 | F30: 400 | G30: 400
A31: Annual Included (attachment) ($) | C31: =C16*C29*C6 -> 14400000 | D31: =D16*D29*D6 -> 21000000 | E31: =E16*E29*E6 -> 30000000 | F31: =F16*F29*F6 -> 36000000 | G31: =G16*G29*G6 -> 42000000
A32: Monthly ($) | C32: =C28*C21 -> 23040000 | D32: =D28*D21 -> 33600000 | E32: =E28*E21 -> 48000000 | F32: =F28*F21 -> 57600000 | G32: =G28*G21 -> 67200000
A33: Annual ($) | C33: =C29*C22 -> 840000 | D33: =D29*D23 -> 1017600 | E33: =E29*E23 -> 2345400 | F33: =F29*F23 -> 4807200 | G33: =G29*G23 -> 10450800
A34: Lifetime ($) | C34: =C30*C23 -> 3360000 | D34: =D30*D24 -> 13568000 | E34: =E30*E24 -> 26060000 | F34: =F30*F24 -> 48072000 | G34: =G30*G24 -> 92896000
A35: Total ($) | C35: =SUM(C31:C34) -> 41640000 | D35: =SUM(D31:D34) -> 69185600 | E35: =SUM(E31:E34) -> 106405400 | F35: =SUM(F31:F34) -> 146479200 | G35: =SUM(G31:G34) -> 212546800
A36: #2 SkyportEnergy Revenue
A37: Homeowners enrollment % | E37: 0.01 | F37: 0.05 | G37: 0.1
A38: Homeowners enrolled | E38: =E37*E13 -> 10015 | F38: =F37*F13 -> 72575 | G38: =G37*G13 -> 201150
A39: TOU Revenue ($) | E39: =E38*Assumptions!$C$16 -> 676012.5 | F39: =F38*Assumptions!$C$16 -> 4898812.5 | G39: =G38*Assumptions!$C$16 -> 13577625
A40: VPP Revenue ($) | F40: =F38*Assumptions!$C$26 -> 4354500 | G40: =G38*Assumptions!$C$26 -> 12069000
A41: Complete ($) | G41: =G38*Assumptions!C45 -> 135977400
...

Sheet Current Model Growth
B1: Inception to FY25 | C1: FY26 | D1: FY27 | E1: FY28 | F1: FY29 | G1: FY30
A2: User & Subscription Growth
A3: Total FIT Volume | C3: 240000 | D3: 350000 | E3: 500000 | F3: 600000 | G3: 700000
A4: RA Volume | C4: 325000 | D4: 400000 | E4: 500000 | F4: 700000 | G4: 750000
A5: Altherma Volume | C5: 840 | D5: 4800 | E5: 13800 | F5: 24000 | G5: 30000
A6: FY FIT Thermostats (all brands) | C6: 240000 | D6: 350000 | E6: 500000 | F6: 600000 | G6: 700000
A7: Total FIT Thermostats (all brands) | B7: 610064 | C7: =B7+C6 -> 850064 | D7: =C7+D6 -> 1200064 | E7: =D7+E6 -> 1700064 | F7: =E7+F6 -> 2300064 | G7: =F7+G6 -> 3000064
A8: FY FIT Connected Thermostats | C8: =C9*C6 -> 144000 | D8: =D9*D6 -> 227500 | E8: =E9*E6 -> 350000 | F8: =F9*F6 -> 450000 | G8: =G9*G6 -> 560000
A9: % of FY FIT Connected Thermostats | B9: =B10/B7 -> 0.55895775 | C9: 0.6 | D9: 0.65 | E9: 0.7 | F9: 0.75 | G9: 0.8
A10: Total FIT Connected Thermostats | B10: 341000 | C10: =B10+C8 -> 485000 | D10: =C10+D8 -> 712500 | E10: =D10+E8 -> 1062500 | F10: =E10+F8 -> 1512500 | G10: =F10+G8 -> 2072500
A11: % of Total FY FIT Connected Thermostats | C11: =C10/C7 -> 0.57054528 | D11: =D10/D7 -> 0.59371834 | E11: =E10/E7 -> 0.62497647 | F11: =F10/F7 -> 0.6575904 | G11: =G10/G7 -> 0.6908186
A12: SkyportHome
A13: Users (%)
A14: FIT | C14: 0.93 | D14: 0.93 | E14: 0.93 | F14: 0.93 | G14: 0.93
A15: DENEB Wi-Fi to SkyportHome Direct | C15: 0.05 | D15: 0.1 | E15: 0.2 | F15: 0.3 | G15: 0.4
A16: Altherma | C16: 0.05 | D16: 0.1 | E16: 0.2 | F16: 0.3 | G16: 0.4
A17: FIT Users only for the FY | C17: =C14*C8 -> 133920 | D17: =D14*D8 -> 211575 | E17: =E14*E8 -> 325500 | F17: =F14*F8 -> 418500 | G17: =G14*G8 -> 520800
A18: RA Users | C18: =C15*C4 -> 16250 | D18: =D15*D4 -> 40000 | E18: =E15*E4 -> 100000 | F18: =F15*F4 -> 210000 | G18: =G15*G4 -> 300000
A19: Altherma Users | C19: =C16*C5 -> 42 | D19: =D16*D5 -> 480 | E19: =E16*E5 -> 2760 | F19: =F16*F5 -> 7200 | G19: =G16*G5 -> 12000
A20: FY Users | C20: =SUM(C17:C19) -> 150212 | D20: =SUM(D17:D19) -> 252055 | E20: =SUM(E17:E19) -> 428260 | F20: =SUM(F17:F19) -> 635700 | G20: =SUM(G17:G19) -> 832800
A21: Total Users | B21: =0.93*B10 -> 317130 | C21: =B21+C17+C18+C19 -> 467342 | D21: =C21+D17+D18+D19 -> 719397 | E21: =D21+E17+E18+E19 -> 1147657 | F21: =E21+F17+F18+F19 -> 1783357 | G21: =F21+G17+G18+G19 -> 2616157
A22: SkyportCare
A23: Total Dealers | B23: 18123
A24: Dealer Participation | B24: 1978 | C24: =C25*$B$23 -> 2718.45 | D24: =D25*$B$23 -> 3624.6 | E24: =E25*$B$23 -> 4530.75 | F24: =F25*$B$23 -> 5436.9 | G24: =G25*$B$23 -> 6343.05
A25: Dealer Participation (%) | B25: =B24/$B$23 -> 0.10914308 | C25: 0.15 | D25: 0.2 | E25: 0.25 | F25: 0.3 | G25: 0.35
A26: Bundled Active Licenses | B26: 9545 | C26: =C30*C21 -> 28040.52 | D26: =D30*D21 -> 57551.76 | E26: =E30*E21 -> 126242.27 | F26: =F30*F21 -> 249669.98 | G26: =G30*G21 -> 470908.26
A27: 1-Year Active Licenses | B27: 318 | C27: =C21*C31 -> 2804.052 | D27: =D21*D31 -> 10790.955 | E27: =E21*E31 -> 28691.425 | F27: =F21*F31 -> 62417.495 | G27: =G21*G31 -> 130807.85
A28: Lifetime Active Licenses | B28: 3320 | C28: =C32*C21 -> 6542.788 | D28: =D32*D21 -> 17984.925 | E28: =E32*E21 -> 40167.995 | F28: =F32*F21 -> 80251.065 | G28: =G32*G21 -> 183130.99
A29: Active Licenses | B29: =SUM(B26:B28) -> 13183 | C29: =SUM(C26:C28) -> 37387.36 | D29: =SUM(D26:D28) -> 86327.64 | E29: =SUM(E26:E28) -> 195101.69 | F29: =SUM(F26:F28) -> 392338.54 | G29: =SUM(G26:G28) -> 784847.1
A30: Active License Penetration | B30: =(B26+B27+B28)/B10 -> 0.038659824 | C30: 0.06 | D30: 0.08 | E30: 0.11 | F30: 0.14 | G30: 0.18
A31: Paid Annual License Penetration | B31: =B27/B10 -> 0.00093255132 | C31: 0.006 | D31: 0.015 | E31: 0.025 | F31: 0.035 | G31: 0.05
A32: Paid Lifetime License Penetration | B32: =B28/B10 -> 0.0097360704 | C32: 0.014 | D32: 0.025 | E32: 0.035 | F32: 0.045 | G32: 0.07
A33: Revenue
A34: #1 SkyportCare License Revenue
A35: Annual License Fee | C35: 60 | D35: 60 | E35: 60 | F35: 60 | G35: 60
A36: Lifetime License Fee | C36: 400 | D36: 400 | E36: 400 | F36: 400 | G36: 400
A37: Bundled Licenses ($) | C37: =C35*C6 -> 14400000 | D37: =D35*D6 -> 21000000 | E37: =E35*E6 -> 30000000 | F37: =F35*F6 -> 36000000 | G37: =G35*G6 -> 42000000
A38: 1-Year Active Licenses ($) | C38: =C35*C27 -> 168243.12 | D38: =D35*D27 -> 647457.3 | E38: =E35*E27 -> 1721485.5 | F38: =F35*F27 -> 3745049.7 | G38: =G35*G27 -> 7848471
A39: Lifetime Active Licenses ($) | C39: =C36*C28 -> 2617115.2 | D39: =D36*D28 -> 7193970 | E39: =E36*E28 -> 16067198 | F39: =F36*F28 -> 32100426 | G39: =G36*G28 -> 73252396
A40: Total ($) | C40: =SUM(C37:C39) -> 17185358 | D40: =SUM(D37:D39) -> 28841427 | E40: =SUM(E37:E39) -> 47788684 | F40: =SUM(F37:F39) -> 71845476 | G40: =SUM(G37:G39) -> 1.2310087e+08
...

Sheet Sheet1
H2: User Scope | J2: Participants / New Licenses | M2: Incremental Revenue | P2: Incremental Margin
B3: Category | C3: Item | D3: Detail | E3: Scope | F3: Dev Cost | G3: Impact | H3: Per User () | I3: Per User (Cost) | J3: Yr1 | K3: Yr2 | L3: Yr3 | M3: Yr1 | N3: Yr2 | O3: Yr3 | P3: Yr1 | Q3: Yr2 | R3: Yr3
B4: HEMS | C4: DR (with SCE and EPRI) | D4: Evaluate DR impact & revenue potential | E4: Investigation, Field Test | F4: $180,000 | G4: Participation Revenue (TBD) | H4: 25 | J4: 200 | K4: 500 | L4: 2000 | M4: =J4*$H4 -> 5000 | N4: =K4*$H4 -> 12500 | O4: =L4*$H4 -> 50000
B5: HEMS | C5: VPP (Leap integration) | D5: Evaluate VPP impact & revenue potential | E5: Investigation, Field Test | F5: $210,000 | G5: Participation Revenue | H5: 60 | J5: 1000 | K5: 10000 | L5: 50000 | M5: =J5*$H5 -> 60000 | N5: =K5*$H5 -> 600000 | O5: =L5*$H5 -> 3000000
B6: HEMS | C6: Time Of Use | D6: Integration to MIDAS TOU Signal (CA ONLY) | E6: Investigation, Field Test | F6: $130,000 | G6: Participation Revenue | H6: 10 | J6: 500 | K6: 2000 | L6: 6000 | M6: =J6*$H6 -> 5000 | N6: =K6*$H6 -> 20000 | O6: =L6*$H6 -> 60000
B7: SkyportCare (Cloud Services) | C7: Release 6 | D7: Remote Charge Validation, Simplified QI, Winter Install, Remote reboot, Multi Language | E7: Upgrade | F7: $620,000 | G7: Increase in Licenses | H7: 60 | I7: 10 | J7: 110000 | K7: 150000 | L7: 100000 | M7: =J7*$H7 -> 6600000 | N7: =K7*$H7 -> 9000000 | O7: =L7*$H7 -> 6000000 | P7: =($H7-$I7)*J7 -> 5500000 | Q7: =($H7-$I7)*K7 -> 7500000 | R7: =($H7-$I7)*L7 -> 5000000
B8: SkyportCare (Cloud Services) | C8: Enterprise | D8: Support Multi Unit Site Licensing and Access Hierarchy | E8: Upgrade | F8: $230,000 | G8: Increase in Licenses | H8: 30 | I8: 10 | J8: 1000 | K8: 5000 | L8: 15000 | M8: =J8*$H8 -> 30000 | N8: =K8*$H8 -> 150000 | O8: =L8*$H8 -> 450000 | P8: =($H8-$I8)*J8 -> 20000 | Q8: =($H8-$I8)*K8 -> 100000 | R8: =($H8-$I8)*L8 -> 300000
