Workbook

Sheet Summary
A1: Monetization Model
A2: Basic (Free) | B2: =SkyportCare!D56 -> 0.72222222
A3: Paid | B3: =SkyportCare!D57 -> 0.33333333
A4: Themes
A5: Energy & Sustainability | B5: =SkyportCare!D49 -> 0.11111111
A6: Ease of Use & Accessibility | B6: =SkyportCare!D50 -> 0.19444444
A7: Trust, Security & Reliability | B7: =SkyportCare!D51 -> 0.33333333
A8: Intelligence & Automation | B8: =SkyportCare!D52 -> 0.25
A9: Engagement & Personalization | B9: =SkyportCare!D53 -> 0.16666667
A11: Initiative Type
A12: New Product Integration | B12: =SkyportCare!E41 -> 0.027777778
A13: New Technical Integration | B13: =SkyportCare!E42 -> 0.055555556
A14: New Interoperability Capability | B14: =SkyportCare!E43 -> 0
A15: New Feature Introduction | B15: =SkyportCare!E44 -> 0.66666667
A16: New Function Introduction | B16: =SkyportCare!E45 -> 0.25
A17: Sustaining | B17: =SkyportCare!E46 -> 0.055555556

Sheet SkyportCare
A1: Feature Group | B1: Feature / Function | C1: Initiative Type | D1: End User Category | E1: Monetization Model | F1: Focus Timeframe | G1: Priority | H1: Development
A2: Dealer Operations & Experience | B2: Dealer On-boarding & Set-up | C2: New Feature Introduction | D2: Trust, Security & Reliability | E2: Basic (Free) | F2: Q2 FY26 | G2: 1 | H2: UI only
B3: Aggregated summary view | C3: New Feature Introduction | D3: Ease of Use & Accessibility | E3: Basic (Free) | F3: Q1 FY26 | G3: 1 | H3: UI only
B4: Dealer Report | C4: New Feature Introduction | D4: Ease of Use & Accessibility | E4: Basic (Free) | F4: Q1 FY26 | G4: 1 | H4: UI only
B5: Homeowner Report | C5: New Feature Introduction | D5: Trust, Security & Reliability | E5: Basic (Free) | F5: Q1 FY26 | G5: 1 | H5: UI only
B6: SkyportHome communication w/homeowner (including Dealer brand) | C6: New Feature Introduction | D6: Engagement & Personalization | E6: Paid | F6: Q2 FY26 | G6: 1 | H6: UI + Data
B7: Ability for dealers to submit feature requests intuitively | C7: New Feature Introduction | D7: Engagement & Personalization | E7: Basic (Free) | F7: Q2 FY26 | G7: 1 | H7: UI + Data
B8: Home Sale Alert | C8: New Feature Introduction | D8: Engagement & Personalization | E8: Basic (Free) | F8: Q2 FY26 | G8: 2 | H8: UI only
B9: Remote Adjust | C9: New Feature Introduction | D9: Ease of Use & Accessibility | E9: Basic (Free) | F9: Q2 FY26 | G9: 1 | H9: UI only
A10: Predictive Maintenance, & Diagnostics | B10: Predictive Maintenance (reminders) | C10: New Feature Introduction | D10: Trust, Security & Reliability | E10: Basic (Free) | F10: Q2 FY26 | G10: 1 | H10: UI only
B11: Technician Support Tools Alerts (minor & critical errors) | C11: New Feature Introduction | D11: Trust, Security & Reliability | E11: Basic (Free) | F11: Q2 FY26 | G11: 1 | H11: UI only
B12: Automated diagnostics - root cause + parts (AI‑Powered) | C12: New Function Introduction | D12: Intelligence & Automation | E12: Paid | F12: FY27+ | G12: 3 | H12: UI + Data + Algorithm
B13: Actionable Alerts (root cause, impact, recommended action) | C13: New Feature Introduction | D13: Trust, Security & Reliability | E13: Basic (Free) | F13: Q3 FY26 | G13: 2 | H13: UI + Data
B14: Automated parts ordering (AI‑Powered) | C14: New Function Introduction | D14: Intelligence & Automation | E14: Paid | F14: FY27+ | G14: 3 | H14: UI + Data + Algorithm
A15: Quality Install, Commissioning & Compliance | B15: Quality Insall | C15: New Feature Introduction | D15: Trust, Security & Reliability | E15: Basic (Free) | F15: Q2 FY26 | G15: 1 | H15: UI + Data
B16: Quality install Climate profiles: Go from basic two to cover all climate zones nationwide | C16: New Feature Introduction | D16: Trust, Security & Reliability | E16: Basic (Free) | F16: Q3 FY26 | G16: 2 | H16: UI + Data
B17: State & Utility Assisted Commissioning compliance | C17: New Technical Integration | D17: Energy & Sustainability | E17: Basic (Free) | F17: FY27+ | G17: 2 | H17: UI + Data
B18: Compliance documentation & reports | C18: New Feature Introduction | D18: Trust, Security & Reliability | E18: Basic (Free) | F18: FY27+ | G18: 2 | H18: UI + Data
A19: Performance, Energy & Runtime Intelligence | B19: Energy runtime - heating/cooling hours/total heating & cooling hours (real-time, historical) for ODU, IDU for selected time frame | C19: New Feature Introduction | D19: Energy & Sustainability | E19: Basic (Free) | F19: Q3 FY26 | G19: 2 | H19: UI + Data
B20: Energy usage (real-time, historical) for ODU, IDU for selected time frame | C20: New Feature Introduction | D20: Energy & Sustainability | E20: Basic (Free) | F20: Q3 FY26 | G20: 2 | H20: UI + Data
B21: ROI & $ Savings Insights (avoided service calls, failure prevention, optimization impact) | C21: New Function Introduction | D21: Intelligence & Automation | E21: Paid | F21: FY27+ | G21: 3 | H21: UI + Data + Algorithm
B22: Energy Usage: System comparison with similar in neighborhood | C22: New Function Introduction | D22: Energy & Sustainability | E22: Paid | F22: Q3 FY26 | G22: 2 | H22: UI + Data
B23: Performance Insights | C23: New Feature Introduction | D23: Intelligence & Automation | E23: Basic (Free) | F23: Q1 FY26 | G23: 1 | H23: UI + Data
A24: Equipment Data – Indoor & Outdoor (All Telemetry) | B24: Support RAQA product line | C24: New Product Integration | D24: Ease of Use & Accessibility | E24: Basic (Free) | F24: Q4 FY26 | G24: 2 | H24: UI + Data
B25: Equipment Data: Key summary metrics, refrigerant diagram w/below visual indication o No refrigerant flow o Low temp low pressure gas o Low temp low pressure liquid o High temp high pressure liquid o High temp high pressure gas | C25: New Feature Introduction | D25: Trust, Security & Reliability | E25: Basic (Free) | F25: Q3 FY26 | G25: 2 | H25: UI + Data
B26: Indoor Equipment Data (real-time, historical) for selected time frame o Cool setpoint o Heat setpoint o Indoor EV opening o Indoor gas pipe temp. o Indoor liquid pipe temp. o Indoor unit On/Off o Indoor unit subcool o Indoor unit superheat o Operation mode o Room temp o Suction air temp | C26: New Feature Introduction | D26: Intelligence & Automation | E26: Basic (Free) | F26: Q3 FY26 | G26: 2 | H26: UI + Data
B27: Outdoor Equipment Data (real-time, historical) for selected time frame Compressor health check o Target condensing temp, Evaporation temp. (TE), Target evaporation temp & Outside air temp. o Compressor discharge pipe temp. Capacity check o Defrost o Oil return o Evaporation temp. (TE), Target evaporation temp &Outside air temp. o Compressor target rotation speed Main heat exchanger component health o Outside air temp. & Condensing temp. (TC) o Heat exchanger gas/liquid pipe temp. (upper) o Subcooling heat exchanger gas pipe temp o Four-way valve (heat exchanger upper & HP/LP gas pipe) o EV pulse (heat/subcooling exchanger upper) Subcool heat exchanger component health o System consumed current o Defrost o Backup operation, Operation mode o Oil return o Restart stand by, Thermo state o Outside air temp. o Compressor & Fan target rotation speed o Four-way valve (heat exchanger upper & HP/LP gas pipe) o EV pulse (heat/subcooling exchanger upper) | C27: New Feature Introduction | D27: Intelligence & Automation | E27: Basic (Free) | F27: Q3 FY26 | G27: 2 | H27: UI + Data
A28: Enterprise, New Construction & Multi‑Tenant | B28: User profile & permissions | C28: New Feature Introduction | D28: Ease of Use & Accessibility | E28: Basic (Free) | F28: Q4 FY26 | G28: 2 | H28: UI + Data
B29: Hierarchical access & data visibility | C29: New Function Introduction | D29: Trust, Security & Reliability | E29: Basic (Free) | F29: Q4 FY26 | G29: 2 | H29: UI + Data
B30: Role-based workflows | C30: New Function Introduction | D30: Ease of Use & Accessibility | E30: Paid | F30: Q4 FY26 | G30: 2 | H30: UI + Data
B31: SkyportHome tenant access linkage | C31: New Feature Introduction | D31: Ease of Use & Accessibility | E31: Basic (Free) | F31: Q4 FY26 | G31: 2 | H31: UI + Data
A32: Premium Capabilities (AI‑Powered) | B32: Autonomous preventative maintenance cycles | C32: New Feature Introduction | D32: Intelligence & Automation | E32: Paid | F32: FY27+ | G32: 3 | H32: UI + Data + Algorithm
B33: Auto‑calibration & optimization | C33: New Technical Integration | D33: Intelligence & Automation | E33: Paid | F33: FY27+ | G33: 3 | H33: UI + Data + Algorithm
B34: Virtual Service Visit (AR) | C34: New Feature Introduction | D34: Intelligence & Automation | E34: Paid | F34: FY27+ | G34: 3 | H34: UI + Data + Algorithm
A35: Dealer–Homeowner Relationship & Growth (AI‑Powered) | B35: Personalized efficiency reports | C35: New Function Introduction | D35: Engagement & Personalization | E35: Paid | F35: FY27+ | G35: 2 | H35: UI + Data
B36: Proactive referral program | C36: New Function Introduction | D36: Engagement & Personalization | E36: Paid | F36: FY27+ | G36: 2 | H36: UI + Data
B37: Predictive upselling (EOL systems) | C37: New Function Introduction | D37: Engagement & Personalization | E37: Paid | F37: FY27+ | G37: 3 | H37: UI + Data + Algorithm
A38: Platform Maintenance | B38: Ongoing platform maintenance | C38: Sustaining | D38: Trust, Security & Reliability | E38: Basic (Free) | F38: FY26 (ongoing) | G38: 1 | H38: UI only
B39: Data accuracy, uptime & security | C39: Sustaining | D39: Trust, Security & Reliability | E39: Basic (Free) | F39: FY26 (ongoing) | G39: 1 | H39: UI + Data
B40: Initiative Type | C40: Owner | D40: Count | E40: Count %
...

Sheet Defintinions
A1: Priority
A2: 1 | B2: Must‑have / Activation & Trust driver (near‑term business impact)
A3: 2 | B3: Differentiation & Monetization enabler (mid‑term)
A4: 3 | B4: Future / Advanced intelligence (longer‑term leverage)
A7: Development
A8: UI only | B8: Uses existing system state and values for display and interaction only. No backend data aggregation, rules, thresholds, interpretation, or decisioning.
A9: UI + Data | B9: Uses existing datasets with backend handling such as aggregation, correlation, rules, or thresholds. May also include new datasets sourced via external APIs, but no prediction, learning, or optimization logic.
A10: UI + Data + Algorithm | B10: Uses data plus decisioning logic to recommend, automate, predict, or optimize outcomes. Includes: - Business‑logic algorithms (rules, heuristics, deterministic logic) - R&D‑level algorithms (product based optimizations, etc.)
